Traceback (most recent call last):
  File "/home/vdsukhov/miniconda3/envs/jbook/lib/python3.10/site-packages/jupyter_cache/executors/utils.py", line 58, in single_nb_execution
    executenb(
  File "/home/vdsukhov/miniconda3/envs/jbook/lib/python3.10/site-packages/nbclient/client.py", line 1204, in execute
    return NotebookClient(nb=nb, resources=resources, km=km, **kwargs).execute()
  File "/home/vdsukhov/miniconda3/envs/jbook/lib/python3.10/site-packages/nbclient/util.py", line 84, in wrapped
    return just_run(coro(*args, **kwargs))
  File "/home/vdsukhov/miniconda3/envs/jbook/lib/python3.10/site-packages/nbclient/util.py", line 62, in just_run
    return loop.run_until_complete(coro)
  File "/home/vdsukhov/miniconda3/envs/jbook/lib/python3.10/asyncio/base_events.py", line 649, in run_until_complete
    return future.result()
  File "/home/vdsukhov/miniconda3/envs/jbook/lib/python3.10/site-packages/nbclient/client.py", line 663, in async_execute
    await self.async_execute_cell(
  File "/home/vdsukhov/miniconda3/envs/jbook/lib/python3.10/site-packages/nbclient/client.py", line 965, in async_execute_cell
    await self._check_raise_for_error(cell, cell_index, exec_reply)
  File "/home/vdsukhov/miniconda3/envs/jbook/lib/python3.10/site-packages/nbclient/client.py", line 862, in _check_raise_for_error
    raise CellExecutionError.from_cell_and_msg(cell, exec_reply_content)
nbclient.exceptions.CellExecutionError: An error occurred while executing the following cell:
------------------
clusters = get_clusters(X.iloc[:, 0:2], centers)
X.cluster = clusters
------------------

[0;31m---------------------------------------------------------------------------[0m
[0;31mNameError[0m                                 Traceback (most recent call last)
Cell [0;32mIn[10], line 1[0m
[0;32m----> 1[0m clusters [38;5;241m=[39m [43mget_clusters[49m(X[38;5;241m.[39miloc[:, [38;5;241m0[39m:[38;5;241m2[39m], centers)
[1;32m      2[0m X[38;5;241m.[39mcluster [38;5;241m=[39m clusters

[0;31mNameError[0m: name 'get_clusters' is not defined
NameError: name 'get_clusters' is not defined

